<?xml version="1.0" ?>
<!-- =================================================================================== -->
<!-- |    This document was autogenerated by xacro from dynamixel_arm.urdf.xacro       | -->
<!-- |    EDITING THIS FILE BY HAND IS NOT RECOMMENDED                                 | -->
<!-- =================================================================================== -->
<robot name="dynamixel_arm" xmlns:xacro="http://ros.org/wiki/xacro">
  <!-- constants for robot dimentions -->
  <!-- inertial for box -->
  <!--xacro:macro 
		name="default_box_inertial" 
		params="mass depth width height x_offset y_offset z_offset">
		<inertial>
			<origin xyz="${x_offset} ${y_offset} ${z_offset}" rpy="0 0 0"/>
			<mass value="${mass}"/>
			<inertia 
				ixx="${1/12*mass*(width*width+height*height)}" ixy="0.0" ixz="0.0" 
				iyy="${1/12*mass*(height*height+depth*depth)}" iyz="0.0" 
				izz="${1/12*mass*(depth*depth+width*width)}"/>
		</inertial>
	</xacro:macro-->
  <!-- inertial for cylinder -->
  <!--xacro:macro 
		name="default_cylinder_inertial" 
		params="mass length radius x_offset y_offset z_offset">
		<inertial>
			<origin xyz="${x_offset} ${y_offset} ${z_offset}" rpy="0 0 0"/>
			<mass value="${mass}"/>
			<inertia 
				ixx="${1/12*mass*(3*radius*radius+length*length)}" ixy="0.0" ixz="0.0" 
				iyy="${1/12*mass*(3*radius*radius+length*length)}" iyz="0.0" 
				izz="${1/2*mass*radius*radius}"/>
		</inertial>
	</xacro:macro-->
  <!-- inertial for box -->
  <!-- inertial for cylinder -->
  <!-- import Rviz color -->
  <material name="white">
    <color rgba="1 1 1 1"/>
  </material>
  <material name="gray">
    <color rgba="0.4 0.4 0.4 1"/>
  </material>
  <material name="lightgray">
    <color rgba="0.45 0.45 0.45 1"/>
  </material>
  <material name="ivory">
    <color rgba="0.54 0.53 0.56 1"/>
  </material>
  <material name="darkgray">
    <color rgba="0.35 0.35 0.35 1"/>
  </material>
  <material name="black">
    <color rgba="0.2 0.2 0.2 1"/>
  </material>
  <material name="laser_black">
    <color rgba="0.1 0.1 0.1 0.0.6"/>
  </material>
  <!-- import Gazebo -->
  <gazebo>
    <plugin filename="libgazebo_ros_control.so" name="ros_contorl">
      <robotNamespace>/dynamixel_arm</robotNamespace>
    </plugin>
  </gazebo>
  <gazebo reference="arm_base_link">
    <material>Gazebo/Orange</material>
  </gazebo>
  <gazebo reference="link1">
    <material>Gazebo/Black</material>
  </gazebo>
  <gazebo reference="link2">
    <material>Gazebo/Orange</material>
  </gazebo>
  <gazebo reference="link3">
    <material>Gazebo/Black</material>
  </gazebo>
  <gazebo reference="link4">
    <material>Gazebo/Orange</material>
  </gazebo>
  <gazebo reference="link5">
    <material>Gazebo/Black</material>
  </gazebo>
  <gazebo reference="link6">
    <material>Gazebo/Orange</material>
  </gazebo>
  <link name="world"/>
  <joint name="fixed" type="fixed">
    <parent link="world"/>
    <child link="arm_base_link"/>
  </joint>
  <!-- Dynamixel Arm -->
  <!--joint name="arm_base_joint" type="fixed">
		<parent link="world"/>
		<child link="arm_base_link"/>
		<origin xyz="${0.720/2-0.040+0.10} 0 ${0.360/2}" rpy="${pi} 0 0"/>
	</joint-->
  <link name="arm_base_link">
    <visual>
      <geometry>
        <cylinder length="0.040" radius="0.040"/>
      </geometry>
      <origin rpy="0 0 0" xyz="0 0 0.02"/>
      <material name="gray"/>
    </visual>
    <collision>
      <geometry>
        <cylinder length="0.040" radius="0.040"/>
      </geometry>
      <origin rpy="0 0 0" xyz="0 0 0.02"/>
    </collision>
    <inertial>
      <origin rpy="0 0 0" xyz="0.0 0.0 -0.02"/>
      <mass value="0.1"/>
      <inertia ixx="1.0" ixy="0.0" ixz="0.0" iyy="1.0" iyz="0.0" izz="1.0"/>
    </inertial>
  </link>
  <joint name="joint1" type="revolute">
    <parent link="arm_base_link"/>
    <child link="link1"/>
    <origin rpy="0 0 0" xyz="0 0 0.04"/>
    <axis xyz="0 0 1"/>
    <limit effort="6.0" lower="-3.05432555556" upper="3.05432555556" velocity="5.75958533333"/>
  </joint>
  <link name="link1">
    <visual>
      <geometry>
        <box size="0.035 0.070 0.050"/>
      </geometry>
      <origin rpy="0 0 0" xyz="0 0 0.025"/>
      <material name="gray"/>
    </visual>
    <collision>
      <geometry>
        <box size="0.035 0.070 0.050"/>
      </geometry>
      <origin rpy="0 0 0" xyz="0 0 0.025"/>
    </collision>
    <inertial>
      <origin rpy="0 0 0" xyz="0.31 0.0 0.025"/>
      <mass value="0.1"/>
      <inertia ixx="1.0" ixy="0.0" ixz="0.0" iyy="1.0" iyz="0.0" izz="1.0"/>
    </inertial>
  </link>
  <joint name="joint2" type="revolute">
    <parent link="link1"/>
    <child link="link2"/>
    <origin rpy="0 0 0" xyz="0 0 0.05"/>
    <axis xyz="0 -1 0"/>
    <limit effort="12.0" lower="-1.65806244444" upper="1.65806244444" velocity="5.75958533333"/>
  </joint>
  <link name="link2">
    <visual>
      <geometry>
        <box size="0.035 0.035 0.150"/>
      </geometry>
      <origin rpy="0 0 0" xyz="0 0 0.075"/>
      <material name="gray"/>
    </visual>
    <collision>
      <geometry>
        <box size="0.035 0.035 0.150"/>
      </geometry>
      <origin rpy="0 0 0" xyz="0 0 0.075"/>
    </collision>
    <inertial>
      <origin rpy="0 0 0" xyz="0.0 0.0 0.15"/>
      <mass value="0.1"/>
      <inertia ixx="1.0" ixy="0.0" ixz="0.0" iyy="1.0" iyz="0.0" izz="1.0"/>
    </inertial>
  </link>
  <joint name="joint3" type="revolute">
    <parent link="link2"/>
    <child link="link3"/>
    <origin rpy="0 0 0" xyz="0 0 0.150"/>
    <axis xyz="0 -1 0"/>
    <limit effort="6.0" lower="-2.61799333333" upper="0.174532888889" velocity="5.75958533333"/>
  </joint>
  <link name="link3">
    <visual>
      <geometry>
        <box size="0.035 0.035 0.060"/>
      </geometry>
      <origin rpy="0 0 0" xyz="0 0 0.03"/>
      <material name="gray"/>
    </visual>
    <collision>
      <geometry>
        <box size="0.035 0.035 0.060"/>
      </geometry>
      <origin rpy="0 0 0" xyz="0 0 0.03"/>
    </collision>
    <inertial>
      <origin rpy="0 0 0" xyz="0.0 0.0 0.06"/>
      <mass value="0.1"/>
      <inertia ixx="1.0" ixy="0.0" ixz="0.0" iyy="1.0" iyz="0.0" izz="1.0"/>
    </inertial>
  </link>
  <joint name="joint4" type="revolute">
    <parent link="link3"/>
    <child link="link4"/>
    <origin rpy="0 0 0" xyz="0 0 0.06"/>
    <axis xyz="0 0 1"/>
    <limit effort="6.0" lower="-3.05432555556" upper="3.05432555556" velocity="5.75958533333"/>
  </joint>
  <link name="link4">
    <visual>
      <geometry>
        <box size="0.035 0.035 0.0975"/>
      </geometry>
      <origin rpy="0 0 0" xyz="0 0 0.04875"/>
      <material name="gray"/>
    </visual>
    <collision>
      <geometry>
        <box size="0.035 0.035 0.0975"/>
      </geometry>
      <origin rpy="0 0 0" xyz="0 0 0.04875"/>
    </collision>
    <inertial>
      <origin rpy="0 0 0" xyz="0.0 0.0 0.04875"/>
      <mass value="0.1"/>
      <inertia ixx="1.0" ixy="0.0" ixz="0.0" iyy="1.0" iyz="0.0" izz="1.0"/>
    </inertial>
  </link>
  <joint name="joint5" type="revolute">
    <parent link="link4"/>
    <child link="link5"/>
    <origin rpy="0 0 0" xyz="0 0 0.0975"/>
    <axis xyz="0 -1 0"/>
    <limit effort="6.0" lower="-1.65806244444" upper="1.65806244444" velocity="5.75958533333"/>
  </joint>
  <link name="link5">
    <visual>
      <origin rpy="0 0 0" xyz="0 0 0.0305"/>
      <geometry>
        <box size="0.024 0.0475 0.061"/>
      </geometry>
      <material name="gray"/>
    </visual>
    <collision>
      <origin rpy="0 0 0" xyz="0 0 0.0305"/>
      <geometry>
        <box size="0.024 0.0475 0.061"/>
      </geometry>
    </collision>
    <visual>
      <origin rpy="-0.52359878 0 0" xyz="0 0.02795 0.068727241"/>
      <geometry>
        <box size="0.034 0.0014 0.019"/>
      </geometry>
      <material name="gray"/>
    </visual>
    <collision>
      <origin rpy="-0.52359878 0 0" xyz="0 0.02795 0.068727241"/>
      <geometry>
        <box size="0.034 0.0014 0.019"/>
      </geometry>
    </collision>
    <visual>
      <origin rpy="0 0 0" xyz="0 0.0327 0.09965"/>
      <geometry>
        <box size="0.034 0.0014 0.0454"/>
      </geometry>
      <material name="gray"/>
    </visual>
    <collision>
      <origin rpy="0 0 0" xyz="0 0.0327 0.09965"/>
      <geometry>
        <box size="0.034 0.0014 0.0454"/>
      </geometry>
    </collision>
    <inertial>
      <origin rpy="0 0 0" xyz="0.0 0.0 0.0305"/>
      <mass value="0.1"/>
      <inertia ixx="1.0" ixy="0.0" ixz="0.0" iyy="1.0" iyz="0.0" izz="1.0"/>
    </inertial>
  </link>
  <joint name="joint6" type="revolute">
    <parent link="link5"/>
    <child link="link6"/>
    <origin rpy="0 0 0" xyz="0 -0.0145 0.045"/>
    <axis xyz="-1 0 0"/>
    <limit effort="6.0" lower="-0.698131555556" upper="0.349065777778" velocity="5.75958533333"/>
  </joint>
  <link name="link6">
    <visual>
      <origin rpy="0 1.57079632675 0" xyz="0 0 0"/>
      <geometry>
        <cylinder length="0.0475" radius="0.012"/>
      </geometry>
      <material name="gray"/>
    </visual>
    <collision>
      <origin rpy="0 1.57079632675 0" xyz="0 0 0"/>
      <geometry>
        <cylinder length="0.0475" radius="0.012"/>
      </geometry>
    </collision>
    <visual>
      <origin rpy="0 0 0" xyz="0 -0.013 0"/>
      <geometry>
        <box size="0.0475 0.026 0.024"/>
      </geometry>
      <material name="gray"/>
    </visual>
    <collision>
      <origin rpy="0 0 0" xyz="0 -0.013 0"/>
      <geometry>
        <box size="0.0475 0.026 0.024"/>
      </geometry>
    </collision>
    <visual>
      <origin rpy="0 0 0" xyz="0 -0.0267 0.023"/>
      <geometry>
        <box size="0.034 0.0014 0.070"/>
      </geometry>
      <material name="gray"/>
    </visual>
    <collision>
      <origin rpy="0 0 0" xyz="0 -0.0267 0.023"/>
      <geometry>
        <box size="0.034 0.0014 0.070"/>
      </geometry>
    </collision>
    <visual>
      <origin rpy="-0.52359878 0 0" xyz="0 -0.0166252378 0.07545"/>
      <geometry>
        <box size="0.034 0.0014 0.040299"/>
      </geometry>
      <material name="gray"/>
    </visual>
    <collision>
      <origin rpy="-0.52359878 0 0" xyz="0 -0.0166252378 0.07545"/>
      <geometry>
        <box size="0.034 0.0014 0.040299"/>
      </geometry>
    </collision>
    <inertial>
      <origin rpy="0 0 0" xyz="0.0 0.0 0.0"/>
      <mass value="0.1"/>
      <inertia ixx="1.0" ixy="0.0" ixz="0.0" iyy="1.0" iyz="0.0" izz="1.0"/>
    </inertial>
  </link>
  <!-- transmission for Dynamixel Arm-->
  <transmission name="tran1">
    <type>transmission_interface/SimpleTransmission</type>
    <joint name="joint1">
      <hardwareInterface>EffortJointInterface</hardwareInterface>
    </joint>
    <actuator name="motor1">
      <hardwareInterface>EffortJointInterface</hardwareInterface>
      <mechanicalReduction>1</mechanicalReduction>
    </actuator>
  </transmission>
  <transmission name="tran2">
    <type>transmission_interface/SimpleTransmission</type>
    <joint name="joint2">
      <hardwareInterface>PositionJointInterface</hardwareInterface>
    </joint>
    <actuator name="motor2">
      <hardwareInterface>PositionJointInterface</hardwareInterface>
      <mechanicalReduction>1</mechanicalReduction>
    </actuator>
  </transmission>
  <transmission name="tran3">
    <type>transmission_interface/SimpleTransmission</type>
    <joint name="joint3">
      <hardwareInterface>PositionJointInterface</hardwareInterface>
    </joint>
    <actuator name="motor3">
      <hardwareInterface>PositionJointInterface</hardwareInterface>
      <mechanicalReduction>1</mechanicalReduction>
    </actuator>
  </transmission>
  <transmission name="tran4">
    <type>transmission_interface/SimpleTransmission</type>
    <joint name="joint4">
      <hardwareInterface>PositionJointInterface</hardwareInterface>
    </joint>
    <actuator name="motor4">
      <hardwareInterface>PositionJointInterface</hardwareInterface>
      <mechanicalReduction>1</mechanicalReduction>
    </actuator>
  </transmission>
  <transmission name="tran5">
    <type>transmission_interface/SimpleTransmission</type>
    <joint name="joint5">
      <hardwareInterface>PositionJointInterface</hardwareInterface>
    </joint>
    <actuator name="motor5">
      <hardwareInterface>PositionJointInterface</hardwareInterface>
      <mechanicalReduction>1</mechanicalReduction>
    </actuator>
  </transmission>
  <transmission name="tran6">
    <type>transmission_interface/SimpleTransmission</type>
    <joint name="joint6">
      <hardwareInterface>PositionJointInterface</hardwareInterface>
    </joint>
    <actuator name="motor6">
      <hardwareInterface>PositionJointInterface</hardwareInterface>
      <mechanicalReduction>1</mechanicalReduction>
    </actuator>
  </transmission>
</robot>

