<?xml version="1.0" ?>
<robot name="dynamixel_arm" xmlns:xacro="http://ros.org/wiki/xacro">

	<!-- constants for robot dimentions -->
	<xacro:property name="pi" value="3.141592"/>	
		
	<!-- inertial for box -->
	<xacro:macro 
		name="default_box_inertial" 
		params="mass depth width height x_offset y_offset z_offset">
		<inertial>
			<origin xyz="${x_offset} ${y_offset} ${z_offset}" rpy="0 0 0"/>
			<mass value="${mass}"/>
			<inertia 
				ixx="1.0" ixy="0.0" ixz="0.0" 
				iyy="1.0" iyz="0.0" 
				izz="1.0"/>
		</inertial>
	</xacro:macro>

	<!-- inertial for cylinder -->
	<xacro:macro 
		name="default_cylinder_inertial" 
		params="mass length radius x_offset y_offset z_offset">
		<inertial>
			<origin xyz="${x_offset} ${y_offset} ${z_offset}" rpy="0 0 0"/>
			<mass value="${mass}"/>
			<inertia 
				ixx="1.0" ixy="0.0" ixz="0.0" 
				iyy="1.0" iyz="0.0" 
				izz="1.0"/>
		</inertial>
	</xacro:macro>

	<!-- import Rviz color -->
	<xacro:include filename="$(find infant_description)/materials/materials.xacro"/>
	<!-- import Gazebo -->
	<xacro:include filename="$(find infant_description)/urdf/dynamixel_arm2.gazebo.xacro"/>
	<link name="world"/>
	
	<joint name="fixed" type="fixed">
		<parent link="world"/>
		<child link="arm_base_link"/>
	</joint>

	<!-- Dynamixel Arm -->
	<!--joint name="arm_base_joint" type="fixed">
		<parent link="world"/>
		<child link="arm_base_link"/>
		<origin xyz="${0.720/2-0.040+0.10} 0 ${0.360/2}" rpy="${pi} 0 0"/>
	</joint-->
	
	<link name="arm_base_link">
		<visual>
			<geometry>
				<mesh filename="package://infant_description/meshes/ARM_BODY.dae" />
			</geometry>
			<origin xyz="0 0 0" rpy="0 0 0"/>
			<material name="gray"/>
		</visual>
		<collision>
			<geometry>
				<box size="0.100 0.100 0.064"/>
			</geometry>
			<origin xyz="0 0 ${0.064/2}" rpy="0 0 0"/>
		</collision>
		<inertial>
			<origin xyz="0.0075 0.0000 0.0327" rpy="0 0 0"/>
			<mass value="0.346"/>
			<inertia 
				ixx="0.000324" ixy="0.0" ixz="0.0" 
				iyy="0.000383" iyz="0.0" 
				izz="0.000381"/>
		</inertial>
	</link>

	<joint name="joint1" type="revolute">
		<parent link="arm_base_link"/>
		<child link="link1"/>
		<origin xyz="0 0 ${0.064}" rpy="0 0 0"/>
		<axis xyz="0 0 1"/>
		<limit effort="6.0" lower="-${175/180*pi}" upper="${175/180*pi}" velocity="${11/6*pi}"/>
	</joint>

	<link name="link1">
		<visual>
			<geometry>
				<mesh filename="package://infant_description/meshes/ARM_JOINT1.dae"/>
			</geometry>
			<origin xyz="0 0 0" rpy="${pi/2} 0 0"/>
			<material name="gray"/>
		</visual>
		<collision>
			<geometry>
				<box size="0.035 0.070 0.063"/>
			</geometry>
			<origin xyz="0 0 ${0.063/2}" rpy="0 0 0"/>
		</collision>
		<inertial>
			<origin xyz="0.0002 0.0367 0.0000" rpy="${pi/2} 0 0"/>
			<mass value="0.506"/>
			<inertia 
				ixx="0.000733" ixy="0.0" ixz="0.0" 
				iyy="0.000495" iyz="0.0" 
				izz="0.000424"/>
		</inertial>
	</link>

	<joint name="joint2" type="revolute">
		<parent link="link1"/>
		<child link="link2"/>
		<origin xyz="0 0 ${0.063}" rpy="0 0 0"/>
		<axis xyz="0 -1 0"/>
		<limit effort="${2*6.0}" lower="-${95/180*pi}" upper="${95/180*pi}" velocity="${11/6*pi}"/>
	</joint>

	<link name="link2">
		<visual>
			<geometry>
				<mesh filename="package://infant_description/meshes/ARM_JOINT2.dae"/>
			</geometry>
			<origin xyz="0 0 0" rpy="0 0 0"/>
			<material name="gray"/>
		</visual>
		<collision>
			<geometry>
				<box size="0.035 0.035 0.250"/>
			</geometry>
			<origin xyz="0 0 ${0.250/2}" rpy="0 0 0"/>
		</collision>
		<inertial>
			<origin xyz="-0.0083 0.0001 0.1509" rpy="0 0 0"/>
			<mass value="0.452"/>
			<inertia 
				ixx="0.003839" ixy="0.0" ixz="0.000159" 
				iyy="0.000378" iyz="0.0" 
				izz="0.000282"/>
		</inertial>
	</link>

	<joint name="joint3" type="revolute">
		<parent link="link2"/>
		<child link="link3"/>
		<origin xyz="0 0 0.250" rpy="0 0 0"/>
		<axis xyz="0 -1 0"/>
		<limit effort="6.0" lower="-${150/180*pi}" upper="${10/180*pi}" velocity="${11/6*pi}"/>
	</joint>

	<link name="link3">
		<visual>
			<geometry>
				<mesh filename="package://infant_description/meshes/ARM_JOINT3.dae"/>
			</geometry>
			<origin xyz="0 0 0" rpy="0 0 0"/>
			<material name="gray"/>
		</visual>
		<collision>
			<geometry>
				<box size="0.035 0.035 0.100"/>
			</geometry>
			<origin xyz="0 0 ${0.100/2}" rpy="0 0 0"/>
		</collision>
		<inertial>
			<origin xyz="-0.0193 0.0003 0.0574" rpy="0 0 0"/>
			<mass value="0.232"/>
			<inertia 
				ixx="0.000230" ixy="0.0" ixz="-0.000164" 
				iyy="0.000231" iyz="0.0" 
				izz="0.000120"/>
		</inertial>
	</link>
		
	<joint name="joint4" type="revolute">
		<parent link="link3"/>
		<child link="link4"/>
		<origin xyz="0 0 0.100" rpy="0 0 0"/>
		<axis xyz="0 0 1"/>
		<limit effort="6.0" lower="-${175/180*pi}" upper="${175/180*pi}" velocity="${11/6*pi}"/>
	</joint>

	<link name="link4">
		<visual>
			<geometry>
				<mesh filename="package://infant_description/meshes/ARM_JOINT4.dae"/>
			</geometry>
			<origin xyz="0 0 0" rpy="${pi/2} 0 0"/>
			<material name="gray"/>
		</visual>
		<collision>
			<geometry>
				<box size="0.035 0.035 0.100"/>
			</geometry>
			<origin xyz="0 0 ${0.100/2}" rpy="0 0 0"/>
		</collision>
		<inertial>
			<origin xyz="0.0000 0.0589 0.0000" rpy="${pi/2} 0 0"/>
			<mass value="0.211"/>
			<inertia 
				ixx="0.000307" ixy="0.0" ixz="-0.000164" 
				iyy="0.000061" iyz="0.0" 
				izz="0.000299"/>
		</inertial>
	</link>

	<joint name="joint5" type="revolute">
		<parent link="link4"/>
		<child link="link5"/>
		<origin xyz="0 0 0.100" rpy="0 0 0"/>
		<axis xyz="0 -1 0"/>
		<limit effort="6.0" lower="-${95/180*pi}" upper="${95/180*pi}" velocity="${11/6*pi}"/>
	</joint>

	<link name="link5">
		<visual>
			<origin xyz="0 0 0" rpy="0 0 0" />
			<geometry>
				<mesh filename="package://infant_description/meshes/ARM_JOINT5.dae"/>
			</geometry>
			<material name="gray"/>
		</visual>
		<collision>
			<origin xyz="0 0 ${0.046/2}" rpy="0 0 0" />
			<geometry>
				<box size="0.024 0.0475 0.046" />
			</geometry>
		</collision>
		<inertial>
			<origin xyz="-0.0013 -0.0012 0.0372" rpy="0 0 0"/>
			<mass value="0.118"/>
			<inertia 
				ixx="0.000063" ixy="0.0" ixz="0.0" 
				iyy="0.000050" iyz="0.0" 
				izz="0.000045"/>
		</inertial>
	</link>

	<joint name="joint6" type="revolute">
		<parent link="link5"/>
		<child link="link6"/>
		<origin xyz="0 -0.0133 0.046" rpy="0 0 0"/>
		<axis xyz="-1 0 0"/>
		<limit effort="6.0" lower="-${40/180*pi}" upper="${20/180*pi}" velocity="${11/6*pi}"/>
	</joint>

	<link name="link6">
		<visual>
			<origin xyz="0 0 0" rpy="0 0 -${pi/2}" />
			<geometry>
				<mesh filename="package://infant_description/meshes/ARM_HAND_A.dae"/>
			</geometry>
			<material name="gray"/>
		</visual>
		<collision>
			<origin xyz="0 0 0" rpy="0 0 ${pi/2}" />
			<geometry>
				<cylinder radius="0.012" length="0.0475" />
			</geometry>
		</collision>
		<inertial>
			<origin xyz="0.0106 -0.0020 0.0249" rpy="0 0 0"/>
			<mass value="0.031"/>
			<inertia 
				ixx="0.000033" ixy="0.0" ixz="0.0" 
				iyy="0.000027" iyz="0.0" 
				izz="0.000012"/>
		</inertial>
	</link>

	<joint name="joint7" type="revolute">
		<parent link="link5"/>
		<child link="link7"/>
		<origin xyz="0 0.0133 0.046" rpy="0 0 0"/>
		<axis xyz="-1 0 0"/>
		<limit effort="6.0" lower="-${40/180*pi}" upper="${20/180*pi}" velocity="${11/6*pi}"/>
	</joint>

	<link name="link7">
		<visual>
			<origin xyz="0 0 0" rpy="0 0 -${pi/2}" />
			<geometry>
				<mesh filename="package://infant_description/meshes/ARM_HAND_B.dae"/>
			</geometry>
			<material name="gray"/>
		</visual>
		<collision>
			<origin xyz="0 0 0" rpy="0 0 -${pi/2}" />
			<geometry>
				<cylinder radius="0.012" length="0.0475" />
			</geometry>
		</collision>
		<inertial>
			<origin xyz="-0.0119 -0.0036 0.0283" rpy="0 0 0"/>
			<mass value="0.027"/>
			<inertia 
				ixx="0.000029" ixy="0.0" ixz="0.0" 
				iyy="0.000024" iyz="0.0" 
				izz="0.000010"/>
		</inertial>
	</link>

	<!-- transmission for Dynamixel Arm-->
	<transmission name="tran1">
		<type>transmission_interface/SimpleTransmission</type>
		<joint name="joint1">
			<hardwareInterface>PositionJointInterface</hardwareInterface>
		</joint>
		<actuator name="motor1">
			<hardwareInterface>PositionJointInterface</hardwareInterface>
			<mechanicalReduction>1</mechanicalReduction>
		</actuator>
	</transmission>

	<transmission name="tran2">
		<type>transmission_interface/SimpleTransmission</type>
		<joint name="joint2">
			<hardwareInterface>PositionJointInterface</hardwareInterface>
		</joint>
		<actuator name="motor2">
			<hardwareInterface>PositionJointInterface</hardwareInterface>
			<mechanicalReduction>1</mechanicalReduction>
		</actuator>
	</transmission>

	<transmission name="tran3">
		<type>transmission_interface/SimpleTransmission</type>
		<joint name="joint3">
			<hardwareInterface>PositionJointInterface</hardwareInterface>
		</joint>
		<actuator name="motor3">
			<hardwareInterface>PositionJointInterface</hardwareInterface>
			<mechanicalReduction>1</mechanicalReduction>
		</actuator>
	</transmission>

	<transmission name="tran4">
		<type>transmission_interface/SimpleTransmission</type>
		<joint name="joint4">
			<hardwareInterface>PositionJointInterface</hardwareInterface>
		</joint>
		<actuator name="motor4">
			<hardwareInterface>PositionJointInterface</hardwareInterface>
			<mechanicalReduction>1</mechanicalReduction>
		</actuator>
	</transmission>

	<transmission name="tran5">
		<type>transmission_interface/SimpleTransmission</type>
		<joint name="joint5">
			<hardwareInterface>PositionJointInterface</hardwareInterface>
		</joint>
		<actuator name="motor5">
			<hardwareInterface>PositionJointInterface</hardwareInterface>
			<mechanicalReduction>1</mechanicalReduction>
		</actuator>
	</transmission>
	
	<transmission name="tran6">
		<type>transmission_interface/SimpleTransmission</type>
		<joint name="joint6">
			<hardwareInterface>PositionJointInterface</hardwareInterface>
		</joint>
		<actuator name="motor6">
			<hardwareInterface>PositionJointInterface</hardwareInterface>
			<mechanicalReduction>1</mechanicalReduction>
		</actuator>
	</transmission>
	
	<transmission name="tran7">
		<type>transmission_interface/SimpleTransmission</type>
		<joint name="joint7">
			<hardwareInterface>PositionJointInterface</hardwareInterface>
		</joint>
		<actuator name="motor7">
			<hardwareInterface>PositionJointInterface</hardwareInterface>
			<mechanicalReduction>1</mechanicalReduction>
		</actuator>
	</transmission>

</robot>

