<?xml version="1.0" ?>
<!-- =================================================================================== -->
<!-- |    This document was autogenerated by xacro from infant_kinect2.urdf.xacro      | -->
<!-- |    EDITING THIS FILE BY HAND IS NOT RECOMMENDED                                 | -->
<!-- =================================================================================== -->
<robot name="infant" xmlns:xacro="http://ros.org/wiki/xacro">
  <!-- constants for robot dimentions -->
  <!--	<property name="cam_py" value="-0.0125" /> Y varies for different configurations. get sets in sensors_urdf -->
  <!-- inertial for box -->
  <!--xacro:macro 
		name="default_box_inertial" 
		params="mass depth width height x_offset y_offset z_offset">
		<inertial>
			<origin xyz="${x_offset} ${y_offset} ${z_offset}" rpy="0 0 0"/>
			<mass value="${mass}"/>
			<inertia 
				ixx="${1/12*mass*(width*width+height*height)}" ixy="0.0" ixz="0.0" 
				iyy="${1/12*mass*(height*height+depth*depth)}" iyz="0.0" 
				izz="${1/12*mass*(depth*depth+width*width)}"/>
		</inertial>
	</xacro:macro-->
  <!-- inertial for cylinder -->
  <!--xacro:macro 
		name="default_cylinder_inertial" 
		params="mass length radius x_offset y_offset z_offset">
		<inertial>
			<origin xyz="${x_offset} ${y_offset} ${z_offset}" rpy="0 0 0"/>
			<mass value="${mass}"/>
			<inertia 
				ixx="${1/12*mass*(3*radius*radius+length*length)}" ixy="0.0" ixz="0.0" 
				iyy="${1/12*mass*(3*radius*radius+length*length)}" iyz="0.0" 
				izz="${1/2*mass*radius*radius}"/>
		</inertial>
	</xacro:macro-->
  <!-- inertial for wheel -->
  <!--xacro:macro 
		name="default_wheel_inertial" 
		params="mass length radius x_offset y_offset z_offset">
		<inertial>
			<origin xyz="${x_offset} ${y_offset} ${z_offset}" rpy="0 0 0"/>	
			<mass value="${mass}"/>
			<inertia 
				ixx="${1/12*mass*(3*radius*radius+length*length)}" ixy="0.0" ixz="0.0" 
				iyy="${1/2*mass*radius*radius}" iyz="0.0" 
				izz="${1/12*mass*(3*radius*radius+length*length)}"/>
		</inertial>
	</xacro:macro-->
  <!-- inertial for box -->
  <!-- inertial for cylinder -->
  <!-- inertial for wheel -->
  <!-- import Rviz color -->
  <material name="white">
    <color rgba="1 1 1 1"/>
  </material>
  <material name="gray">
    <color rgba="0.4 0.4 0.4 1"/>
  </material>
  <material name="lightgray">
    <color rgba="0.45 0.45 0.45 1"/>
  </material>
  <material name="ivory">
    <color rgba="0.54 0.53 0.56 1"/>
  </material>
  <material name="darkgray">
    <color rgba="0.35 0.35 0.35 1"/>
  </material>
  <material name="black">
    <color rgba="0.2 0.2 0.2 1"/>
  </material>
  <material name="laser_black">
    <color rgba="0.1 0.1 0.1 0.0.6"/>
  </material>
  <!-- import all Gazebo-customization elements, including Gazebo colors -->
  <gazebo reference="battery_link">
    <material>Gazebo/FlatBlack</material>
    <mu1>0.4</mu1>
    <mu2>0.4</mu2>
  </gazebo>
  <gazebo reference="rocker_bogie_back_left_link">
    <material>Gazebo/Road</material>
    <mu1>0.4</mu1>
    <mu2>0.4</mu2>
  </gazebo>
  <gazebo reference="rocker_bogie_back_right_link">
    <material>Gazebo/Road</material>
    <mu1>0.4</mu1>
    <mu2>0.4</mu2>
  </gazebo>
  <gazebo reference="rocker_bogie_front_left_link">
    <material>Gazebo/Road</material>
    <mu1>0.4</mu1>
    <mu2>0.4</mu2>
  </gazebo>
  <gazebo reference="rocker_bogie_front_right_link">
    <material>Gazebo/Road</material>
    <mu1>0.4</mu1>
    <mu2>0.4</mu2>
  </gazebo>
  <gazebo reference="caster_small_left_link">
    <material>Gazebo/Grey</material>
    <mu1>0.0</mu1>
    <mu2>0.0</mu2>
  </gazebo>
  <gazebo reference="caster_small_right_link">
    <material>Gazebo/Grey</material>
    <mu1>0.0</mu1>
    <mu2>0.0</mu2>
  </gazebo>
  <gazebo reference="caster_large_left_link">
    <material>Gazebo/Grey</material>
    <mu1>0.0</mu1>
    <mu2>0.0</mu2>
  </gazebo>
  <gazebo reference="caster_large_right_link">
    <material>Gazebo/Grey</material>
    <mu1>0.0</mu1>
    <mu2>0.0</mu2>
  </gazebo>
  <gazebo reference="wheel_left_link">
    <material>Gazebo/DarkGrey</material>
    <mu1>1.0</mu1>
    <mu2>1.0</mu2>
  </gazebo>
  <gazebo reference="wheel_right_link">
    <material>Gazebo/DarkGrey</material>
    <mu1>1.0</mu1>
    <mu2>1.0</mu2>
  </gazebo>
  <gazebo reference="wheel_small_left_link">
    <material>Gazebo/Black</material>
    <mu1>0.2</mu1>
    <mu2>0.0</mu2>
  </gazebo>
  <gazebo reference="wheel_small_right_link">
    <material>Gazebo/Black</material>
    <mu1>0.2</mu1>
    <mu2>0.0</mu2>
  </gazebo>
  <gazebo reference="wheel_large_left_link">
    <material>Gazebo/Black</material>
    <mu1>0.2</mu1>
    <mu2>0.0</mu2>
  </gazebo>
  <gazebo reference="wheel_large_right_link">
    <material>Gazebo/Black</material>
    <mu1>0.2</mu1>
    <mu2>0.0</mu2>
  </gazebo>
  <gazebo reference="box_link">
    <material>Gazebo/White</material>
    <selfCollide>true</selfCollide>
  </gazebo>
  <gazebo reference="mast_link">
    <material>Gazebo/Grey</material>
  </gazebo>
  <gazebo reference="table_link">
    <material>Gazebo/Grey</material>
  </gazebo>
  <gazebo reference="velodyne_base_link">
    <material>Gazebo/Gold</material>
    <mu1>0.0</mu1>
    <mu2>0.0</mu2>
  </gazebo>
  <gazebo reference="velodyne_top_link">
    <material>Gazebo/Gold</material>
    <mu1>0.0</mu1>
    <mu2>0.0</mu2>
  </gazebo>
  <gazebo reference="velodyne_laser_link">
    <material>Gazebo/Black</material>
  </gazebo>
  <gazebo reference="kinect_base_link">
    <material>Gazebo/Grey</material>
  </gazebo>
  <gazebo reference="arm_base_link">
    <material>Gazebo/Orange</material>
    <!-- <selfCollide>true</selfCollide>	 -->
  </gazebo>
  <gazebo reference="link1">
    <material>Gazebo/Black</material>
    <mu1>0.2</mu1>
    <mu2>0.2</mu2>
    <!-- <selfCollide>true</selfCollide>	 -->
  </gazebo>
  <gazebo reference="link2">
    <material>Gazebo/Orange</material>
    <mu1>0.2</mu1>
    <mu2>0.2</mu2>
    <!-- <selfCollide>true</selfCollide>	 -->
  </gazebo>
  <gazebo reference="link3">
    <material>Gazebo/Black</material>
    <mu1>0.2</mu1>
    <mu2>0.2</mu2>
    <!-- <selfCollide>true</selfCollide>	 -->
  </gazebo>
  <gazebo reference="link4">
    <material>Gazebo/Orange</material>
    <mu1>0.2</mu1>
    <mu2>0.2</mu2>
    <!-- <selfCollide>true</selfCollide>	 -->
  </gazebo>
  <gazebo reference="link5">
    <material>Gazebo/Black</material>
    <mu1>1.0</mu1>
    <mu2>1.0</mu2>
    <!-- <selfCollide>true</selfCollide>	 -->
  </gazebo>
  <gazebo reference="link6">
    <material>Gazebo/Orange</material>
    <mu1>1.0</mu1>
    <mu2>1.0</mu2>
    <!-- <selfCollide>true</selfCollide>	 -->
  </gazebo>
  <gazebo reference="link7">
    <material>Gazebo/Black</material>
    <mu1>1.0</mu1>
    <mu2>1.0</mu2>
    <!-- <selfCollide>true</selfCollide>	 -->
  </gazebo>
  <!-- imu -->
  <gazebo>
    <plugin filename="libgazebo_ros_imu.so" name="imu_controller">
      <updateRate>100.0</updateRate>
      <topicName>/infant/imu_data</topicName>
      <frameName>base_link</frameName>
      <bodyName>base_link</bodyName>
      <frameId>base_link</frameId>
      <topicName>/rinfant/imu_data</topicName>
      <serviceName>/default_imu</serviceName>
      <xyzOffset>0 0 0</xyzOffset>
      <rpyOffset>0 0 0</rpyOffset>
      <!-- deprecated -->
      <gaussianNoise>0</gaussianNoise>
      <!-- deprecated -->
      <accelDrift>0.5 0.5 0.5</accelDrift>
      <accelGaussianNoise>0.35 0.35 0.3</accelGaussianNoise>
      <rateDrift>0.0 0.0 0.0</rateDrift>
      <rateGaussianNoise>0.00 0.00 0.00</rateGaussianNoise>
      <headingDrift>0.0</headingDrift>
      <headingGaussianNoise>0.00</headingGaussianNoise>
    </plugin>
  </gazebo>
  <!-- velodyne -->
  <!--gazebo reference="velodyne_laser_link">
		<sensor type="ray" name="head_velodyne_sensor">
			<visualize>false</visualize>
			<update_rate>1</update_rate>
			<ray>
				<scan>
					<horizontal>
						<samples>1080</samples>
						<resolution>1</resolution>
						<min_angle>-3.1415</min_angle>
						<max_angle>3.1415</max_angle>
					</horizontal>
					<vertical>
						<samples>32</samples>
						<resolution>1</resolution>
						<min_angle>-0.186227</min_angle>
						<max_angle>0.535292</max_angle>
					</vertical>
				</scan>
				<range>
					<min>0.10</min>
					<max>70.0</max>
					<resolution>0.01</resolution>
				</range>
				<noise>
					<type>gaussian</type>
					<mean>0.0</mean>
					<stddev>0.01</stddev>
				</noise>
			</ray>
			<plugin name="gazebo_ros_head_velodyne_controller" filename="libgazebo_ros_block_laser.so">
				<alwaysOn>true</alwaysOn>
				<updateRate>1</updateRate>
				<topicName>/infant/velodyne_points</topicName>
				<frameName>velodyne_laser_link</frameName>
			</plugin>
		</sensor>
	</gazebo-->
  <!-- hokuyo -->
  <!--gazebo reference="velodyne_laser_link">
		<sensor type="ray" name="hokuyo_sensor">
			<pose>0 0 0 0 0 0</pose>
			<visualize>true</visualize>
			<update_rate>500</update_rate>
			<ray>
				<scan>
					<horizontal>
						<samples>32</samples>
						<resolution>1</resolution>
						<min_angle>-0.186227</min_angle>
						<max_angle>0.535292</max_angle>
					</horizontal>
				</scan>
				<range>
					<min>1.0</min>
					<max>70.0</max>
					<resolution>0.01</resolution>
				</range>
				<noise>
					<type>gaussian</type>
					<mean>0.0</mean>
					<stddev>0.0</stddev>
				</noise>
			</ray>
			<plugin name="gazebo_ros_hokuyo_controller" filename="libgazebo_ros_laser.so">
				<topicName>/infant/laser/scan</topicName>
				<frameName>velodyne_laser_link</frameName>
			</plugin>
		</sensor>
	</gazebo>

	<gazebo reference="velodyne_laser2_link">
		<sensor type="ray" name="hokuyo_sensor_2">
			<pose>0 0 0 0 0 0</pose>
			<visualize>true</visualize>
			<update_rate>500</update_rate>
			<ray>
				<scan>
					<horizontal>
						<samples>32</samples>
						<resolution>1</resolution>
						<min_angle>-0.186227</min_angle>
						<max_angle>0.535292</max_angle>
					</horizontal>
				</scan>
				<range>
					<min>1.0</min>
					<max>70.0</max>
					<resolution>0.01</resolution>
				</range>
				<noise>
					<type>gaussian</type>
					<mean>0.0</mean>
					<stddev>0.0</stddev>
				</noise>
			</ray>
			<plugin name="gazebo_ros_hokuyo_controller" filename="libgazebo_ros_laser.so">
				<topicName>/infant/laser/scan2</topicName>
				<frameName>velodyne_laser2_link</frameName>
			</plugin>
		</sensor>
	</gazebo>
	
	<gazebo reference="velodyne_laser3_link">
		<sensor type="ray" name="hokuyo_sensor_3">
			<pose>0 0 0 0 0 0</pose>
			<visualize>true</visualize>
			<update_rate>500</update_rate>
			<ray>
				<scan>
					<horizontal>
						<samples>32</samples>
						<resolution>1</resolution>
						<min_angle>-0.186227</min_angle>
						<max_angle>0.535292</max_angle>
					</horizontal>
				</scan>
				<range>
					<min>1.0</min>
					<max>70.0</max>
					<resolution>0.01</resolution>
				</range>
				<noise>
					<type>gaussian</type>
					<mean>0.0</mean>
					<stddev>0.0</stddev>
				</noise>
			</ray>
			<plugin name="gazebo_ros_hokuyo_controller" filename="libgazebo_ros_laser.so">
				<topicName>/infant/laser/scan3</topicName>
				<frameName>velodyne_laser3_link</frameName>
			</plugin>
		</sensor>
	</gazebo>
	
	<gazebo reference="velodyne_laser4_link">
		<sensor type="ray" name="hokuyo_sensor_4">
			<pose>0 0 0 0 0 0</pose>
			<visualize>true</visualize>
			<update_rate>500</update_rate>
			<ray>
				<scan>
					<horizontal>
						<samples>32</samples>
						<resolution>1</resolution>
						<min_angle>-0.186227</min_angle>
						<max_angle>0.535292</max_angle>
					</horizontal>
				</scan>
				<range>
					<min>1.0</min>
					<max>70.0</max>
					<resolution>0.01</resolution>
				</range>
				<noise>
					<type>gaussian</type>
					<mean>0.0</mean>
					<stddev>0.0</stddev>
				</noise>
			</ray>
			<plugin name="gazebo_ros_hokuyo_controller" filename="libgazebo_ros_laser.so">
				<topicName>/infant/laser/scan4</topicName>
				<frameName>velodyne_laser4_link</frameName>
			</plugin>
		</sensor>
	</gazebo>
	
	<gazebo reference="velodyne_laser5_link">
		<sensor type="ray" name="hokuyo_sensor_5">
			<pose>0 0 0 0 0 0</pose>
			<visualize>true</visualize>
			<update_rate>500</update_rate>
			<ray>
				<scan>
					<horizontal>
						<samples>32</samples>
						<resolution>1</resolution>
						<min_angle>-0.186227</min_angle>
						<max_angle>0.535292</max_angle>
					</horizontal>
				</scan>
				<range>
					<min>1.0</min>
					<max>70.0</max>
					<resolution>0.01</resolution>
				</range>
				<noise>
					<type>gaussian</type>
					<mean>0.0</mean>
					<stddev>0.0</stddev>
				</noise>
			</ray>
			<plugin name="gazebo_ros_hokuyo_controller" filename="libgazebo_ros_laser.so">
				<topicName>/infant/laser/scan5</topicName>
				<frameName>velodyne_laser5_link</frameName>
			</plugin>
		</sensor>
	</gazebo>
	
	<gazebo reference="velodyne_laser6_link">
		<sensor type="ray" name="hokuyo_sensor_6">
			<pose>0 0 0 0 0 0</pose>
			<visualize>true</visualize>
			<update_rate>500</update_rate>
			<ray>
				<scan>
					<horizontal>
						<samples>32</samples>
						<resolution>1</resolution>
						<min_angle>-0.186227</min_angle>
						<max_angle>0.535292</max_angle>
					</horizontal>
				</scan>
				<range>
					<min>1.0</min>
					<max>70.0</max>
					<resolution>0.01</resolution>
				</range>
				<noise>
					<type>gaussian</type>
					<mean>0.0</mean>
					<stddev>0.0</stddev>
				</noise>
			</ray>
			<plugin name="gazebo_ros_hokuyo_controller" filename="libgazebo_ros_laser.so">
				<topicName>/infant/laser/scan6</topicName>
				<frameName>velodyne_laser6_link</frameName>
			</plugin>
		</sensor>
	</gazebo>
	
	<gazebo reference="velodyne_laser7_link">
		<sensor type="ray" name="hokuyo_sensor_7">
			<pose>0 0 0 0 0 0</pose>
			<visualize>true</visualize>
			<update_rate>500</update_rate>
			<ray>
				<scan>
					<horizontal>
						<samples>32</samples>
						<resolution>1</resolution>
						<min_angle>-0.186227</min_angle>
						<max_angle>0.535292</max_angle>
					</horizontal>
				</scan>
				<range>
					<min>1.0</min>
					<max>70.0</max>
					<resolution>0.01</resolution>
				</range>
				<noise>
					<type>gaussian</type>
					<mean>0.0</mean>
					<stddev>0.0</stddev>
				</noise>
			</ray>
			<plugin name="gazebo_ros_hokuyo_controller" filename="libgazebo_ros_laser.so">
				<topicName>/infant/laser/scan7</topicName>
				<frameName>velodyne_laser7_link</frameName>
			</plugin>
		</sensor>
	</gazebo>

	<gazebo reference="velodyne_laser8_link">
		<sensor type="ray" name="hokuyo_sensor_8">
			<pose>0 0 0 0 0 0</pose>
			<visualize>true</visualize>
			<update_rate>500</update_rate>
			<ray>
				<scan>
					<horizontal>
						<samples>32</samples>
						<resolution>1</resolution>
						<min_angle>-0.186227</min_angle>
						<max_angle>0.535292</max_angle>
					</horizontal>
				</scan>
				<range>
					<min>1.0</min>
					<max>70.0</max>
					<resolution>0.01</resolution>
				</range>
				<noise>
					<type>gaussian</type>
					<mean>0.0</mean>
					<stddev>0.0</stddev>
				</noise>
			</ray>
			<plugin name="gazebo_ros_hokuyo_controller" filename="libgazebo_ros_laser.so">
				<topicName>/infant/laser/scan8</topicName>
				<frameName>velodyne_laser8_link</frameName>
			</plugin>
		</sensor>
	</gazebo-->
  <!-- kinect -->
  <gazebo reference="camera_link">
    <sensor name="camera" type="depth">
      <always_on>true</always_on>
      <update_rate>20.0</update_rate>
      <camera>
        <horizontal_fov>1.04719733333</horizontal_fov>
        <image>
          <format>R8G8B8</format>
          <width>640</width>
          <height>480</height>
        </image>
        <clip>
          <near>0.05</near>
          <far>8.0</far>
        </clip>
      </camera>
      <plugin filename="libgazebo_ros_openni_kinect.so" name="kinect_camera_controller">
        <cameraName>camera</cameraName>
        <alwaysOn>true</alwaysOn>
        <updateRate>10</updateRate>
        <imageTopicName>rgb/image_raw</imageTopicName>
        <depthImageTopicName>depth/image_raw</depthImageTopicName>
        <pointCloudTopicName>depth/points</pointCloudTopicName>
        <cameraInfoTopicName>rgb/camera_info</cameraInfoTopicName>
        <depthImageCameraInfoTopicName>depth/camera_info</depthImageCameraInfoTopicName>
        <frameName>camera_depth_optical_frame</frameName>
        <hackBaseline>0.1</hackBaseline>
        <distortion_k1>0.0</distortion_k1>
        <distortion_k2>0.0</distortion_k2>
        <distortion_k3>0.0</distortion_k3>
        <distortion_t1>0.0</distortion_t1>
        <distortion_t2>0.0</distortion_t2>
        <pointCloudCutoff>0.4</pointCloudCutoff>
        <pointCloudCutoffMax>100.0</pointCloudCutoffMax>
      </plugin>
    </sensor>
  </gazebo>
  <!-- ros_control plugin -->
  <gazebo>
    <plugin filename="libgazebo_ros_control.so" name="gazebo_ros_control">
      <robotNamespace>/infant</robotNamespace>
    </plugin>
  </gazebo>
  <link name="world"/>
  <joint name="fixed" type="fixed">
    <parent link="world"/>
    <child link="base_link"/>
    <origin rpy="0 0 0" xyz="0 0 0"/>
  </joint>
  <link name="base_link"/>
  <joint name="base_to_battery_joint" type="fixed">
    <parent link="base_link"/>
    <child link="battery_link"/>
    <!-- <origin xyz="0 0 0.140" rpy="0 0 0"/> -->
    <origin rpy="0 0 0" xyz="0 0 0.143"/>
  </joint>
  <link name="battery_link">
    <visual>
      <geometry>
        <box size="0.42 0.17 0.37"/>
      </geometry>
      <origin rpy="0 0 0" xyz="0 0 0.085"/>
      <material name="black"/>
    </visual>
    <collision>
      <geometry>
        <box size="0.42 0.17 0.37"/>
      </geometry>
      <origin rpy="0 0 0" xyz="0 0 0.085"/>
    </collision>
    <inertial>
      <origin rpy="0 0 0" xyz="0.0 0.0 0.085"/>
      <mass value="40"/>
      <inertia ixx="1.0" ixy="0.0" ixz="0.0" iyy="1.0" iyz="0.0" izz="1.0"/>
    </inertial>
  </link>
  <joint name="rocker_bogie_back_left_joint" type="fixed">
    <parent link="battery_link"/>
    <child link="rocker_bogie_back_left_link"/>
    <origin rpy="0 0 0" xyz="0 0.085 0"/>
  </joint>
  <link name="rocker_bogie_back_left_link">
    <visual>
      <geometry>
        <mesh filename="package://infant_description/meshes/rocker_bogie_parts_back_left.dae"/>
      </geometry>
      <origin rpy="0 3.141592 0" xyz="0 -0.0 0"/>
    </visual>
    <collision>
      <geometry>
        <box size="0.46056514 0.09383127 0.23"/>
      </geometry>
      <origin rpy="0 0 0" xyz="-0.15028257 0.046915635 0.035"/>
    </collision>
    <inertial>
      <origin rpy="0 0 0" xyz="-0.15028257 0.046915635 0.035"/>
      <mass value="5"/>
      <inertia ixx="1.0" ixy="0.0" ixz="0.0" iyy="1.0" iyz="0.0" izz="1.0"/>
    </inertial>
  </link>
  <joint name="rocker_bogie_back_right_joint" type="fixed">
    <parent link="battery_link"/>
    <child link="rocker_bogie_back_right_link"/>
    <origin rpy="0 0 0" xyz="0 -0.085 0"/>
  </joint>
  <link name="rocker_bogie_back_right_link">
    <visual>
      <geometry>
        <mesh filename="package://infant_description/meshes/rocker_bogie_parts_back_right.dae"/>
      </geometry>
      <origin rpy="0 3.141592 0" xyz="0 -0.02 0"/>
    </visual>
    <collision>
      <geometry>
        <box size="0.46056514 0.09383127 0.23"/>
      </geometry>
      <origin rpy="0 0 0" xyz="-0.15028257 -0.046915635 0.035"/>
    </collision>
    <inertial>
      <origin rpy="0 0 0" xyz="-0.15028257 -0.046915635 0.035"/>
      <mass value="5"/>
      <inertia ixx="1.0" ixy="0.0" ixz="0.0" iyy="1.0" iyz="0.0" izz="1.0"/>
    </inertial>
  </link>
  <joint name="rocker_bogie_front_left_joint" type="fixed">
    <parent link="battery_link"/>
    <child link="rocker_bogie_front_left_link"/>
    <origin rpy="0 0 0" xyz="0 0.105 0"/>
  </joint>
  <link name="rocker_bogie_front_left_link">
    <visual>
      <geometry>
        <mesh filename="package://infant_description/meshes/rocker_bogie_parts_front_left.dae"/>
      </geometry>
      <origin rpy="3.141592 0 0" xyz="0 0.02 0"/>
    </visual>
    <collision>
      <geometry>
        <box size="0.42535668 0.11153324 0.23"/>
      </geometry>
      <origin rpy="0 0 0" xyz="0.13267834 0.05576662 0.035"/>
    </collision>
    <inertial>
      <origin rpy="0 0 0" xyz="0.13267834 0.05576662 0.035"/>
      <mass value="5"/>
      <inertia ixx="1.0" ixy="0.0" ixz="0.0" iyy="1.0" iyz="0.0" izz="1.0"/>
    </inertial>
  </link>
  <joint name="rocker_bogie_front_right_joint" type="fixed">
    <parent link="battery_link"/>
    <child link="rocker_bogie_front_right_link"/>
    <origin rpy="0 0 0" xyz="0 -0.105 0"/>
  </joint>
  <link name="rocker_bogie_front_right_link">
    <visual>
      <geometry>
        <mesh filename="package://infant_description/meshes/rocker_bogie_parts_front_right.dae"/>
      </geometry>
      <origin rpy="3.141592 0 0" xyz="0 0.0 0"/>
    </visual>
    <collision>
      <geometry>
        <box size="0.42535668 0.11153324 0.23"/>
      </geometry>
      <origin rpy="0 0 0" xyz="0.13267834 -0.05576662 0.035"/>
    </collision>
    <inertial>
      <origin rpy="0 0 0" xyz="0.13267834 -0.05576662 0.035"/>
      <mass value="5"/>
      <inertia ixx="1.0" ixy="0.0" ixz="0.0" iyy="1.0" iyz="0.0" izz="1.0"/>
    </inertial>
  </link>
  <joint name="caster_small_left_joint" type="fixed">
    <parent link="rocker_bogie_back_left_link"/>
    <child link="caster_small_left_link"/>
    <origin rpy="0 0 0" xyz="-0.360 0.075 0.070"/>
    <axis xyz="0 0 1"/>
  </joint>
  <link name="caster_small_left_link">
    <visual>
      <geometry>
        <mesh filename="package://infant_description/meshes/caster_small.dae"/>
      </geometry>
      <origin rpy="-1.570796 0 1.570796" xyz="0 0 0"/>
    </visual>
    <collision>
      <geometry>
        <cylinder length="0.065" radius="0.01"/>
      </geometry>
      <origin rpy="0 0 0" xyz="0 0 -0.0325"/>
    </collision>
    <inertial>
      <origin rpy="0 0 0" xyz="0.0 0.0 -0.0325"/>
      <mass value="0.5"/>
      <inertia ixx="1.0" ixy="0.0" ixz="0.0" iyy="1.0" iyz="0.0" izz="1.0"/>
    </inertial>
  </link>
  <joint name="caster_small_right_joint" type="fixed">
    <parent link="rocker_bogie_back_right_link"/>
    <child link="caster_small_right_link"/>
    <origin rpy="0 0 0" xyz="-0.360 -0.075 0.070"/>
    <axis xyz="0 0 1"/>
  </joint>
  <link name="caster_small_right_link">
    <visual>
      <geometry>
        <mesh filename="package://infant_description/meshes/caster_small.dae"/>
      </geometry>
      <origin rpy="-1.570796 0 1.570796" xyz="0 0 0"/>
    </visual>
    <collision>
      <geometry>
        <cylinder length="0.065" radius="0.01"/>
      </geometry>
      <origin rpy="0 0 0" xyz="0 0 -0.0325"/>
    </collision>
    <inertial>
      <origin rpy="0 0 0" xyz="0.0 0.0 -0.0325"/>
      <mass value="0.5"/>
      <inertia ixx="1.0" ixy="0.0" ixz="0.0" iyy="1.0" iyz="0.0" izz="1.0"/>
    </inertial>
  </link>
  <joint name="caster_large_left_joint" type="fixed">
    <parent link="rocker_bogie_front_left_link"/>
    <child link="caster_large_left_link"/>
    <origin rpy="0 0 0" xyz="0.330 0.095 0.070"/>
    <axis xyz="0 0 1"/>
  </joint>
  <link name="caster_large_left_link">
    <visual>
      <geometry>
        <mesh filename="package://infant_description/meshes/caster_large.dae"/>
      </geometry>
      <origin rpy="-1.570796 0 1.570796" xyz="0 0 0"/>
    </visual>
    <collision>
      <geometry>
        <cylinder length="0.045" radius="0.01"/>
      </geometry>
      <origin rpy="0 0 0" xyz="0 0 -0.0225"/>
    </collision>
    <inertial>
      <origin rpy="0 0 0" xyz="0.0 0.0 -0.0225"/>
      <mass value="0.5"/>
      <inertia ixx="1.0" ixy="0.0" ixz="0.0" iyy="1.0" iyz="0.0" izz="1.0"/>
    </inertial>
  </link>
  <joint name="caster_large_right_joint" type="fixed">
    <parent link="rocker_bogie_front_right_link"/>
    <child link="caster_large_right_link"/>
    <origin rpy="0 0 0" xyz="0.330 -0.095 0.070"/>
    <axis xyz="0 0 1"/>
  </joint>
  <link name="caster_large_right_link">
    <visual>
      <geometry>
        <mesh filename="package://infant_description/meshes/caster_large.dae"/>
      </geometry>
      <origin rpy="-1.570796 0 1.570796" xyz="0 0 0"/>
    </visual>
    <collision>
      <geometry>
        <cylinder length="0.045" radius="0.01"/>
      </geometry>
      <origin rpy="0 0 0" xyz="0 0 -0.0225"/>
    </collision>
    <inertial>
      <origin rpy="0 0 0" xyz="0.0 0.0 -0.0225"/>
      <mass value="0.5"/>
      <inertia ixx="1.0" ixy="0.0" ixz="0.0" iyy="1.0" iyz="0.0" izz="1.0"/>
    </inertial>
  </link>
  <joint name="wheel_left_joint" type="continuous">
    <parent link="rocker_bogie_front_left_link"/>
    <child link="wheel_left_link"/>
    <origin rpy="0 0 0" xyz="0 0.145 0"/>
    <axis xyz="0 1 0"/>
  </joint>
  <link name="wheel_left_link">
    <visual>
      <geometry>
        <cylinder length="0.100" radius="0.14240"/>
      </geometry>
      <origin rpy="1.570796 0 0" xyz="0 0 0"/>
      <material name="ivory"/>
    </visual>
    <collision>
      <geometry>
        <cylinder length="0.100" radius="0.14240"/>
      </geometry>
      <origin rpy="1.570796 0 0" xyz="0 0 0"/>
    </collision>
    <inertial>
      <origin rpy="0 0 0" xyz="0.0 0.0 0.0"/>
      <mass value="4"/>
      <inertia ixx="1.0" ixy="0.0" ixz="0.0" iyy="1.0" iyz="0.0" izz="1.0"/>
    </inertial>
  </link>
  <joint name="wheel_right_joint" type="continuous">
    <parent link="rocker_bogie_front_right_link"/>
    <child link="wheel_right_link"/>
    <origin rpy="0 0 0" xyz="0 -0.145 0"/>
    <axis xyz="0 1 0"/>
  </joint>
  <link name="wheel_right_link">
    <visual>
      <geometry>
        <cylinder length="0.100" radius="0.14240"/>
      </geometry>
      <origin rpy="1.570796 0 0" xyz="0 0 0"/>
      <material name="ivory"/>
    </visual>
    <collision>
      <geometry>
        <cylinder length="0.100" radius="0.14240"/>
      </geometry>
      <origin rpy="1.570796 0 0" xyz="0 0 0"/>
    </collision>
    <inertial>
      <origin rpy="0 0 0" xyz="0.0 0.0 0.0"/>
      <mass value="4"/>
      <inertia ixx="1.0" ixy="0.0" ixz="0.0" iyy="1.0" iyz="0.0" izz="1.0"/>
    </inertial>
  </link>
  <joint name="wheel_small_left_joint" type="fixed">
    <parent link="caster_small_left_link"/>
    <child link="wheel_small_left_link"/>
    <origin rpy="0 0 0" xyz="0 0 -0.145"/>
    <axis xyz="0 1 0"/>
  </joint>
  <link name="wheel_small_left_link">
    <visual>
      <geometry>
        <cylinder length="0.030" radius="0.070"/>
      </geometry>
      <origin rpy="1.570796 0 0" xyz="0 0 0"/>
      <material name="black"/>
    </visual>
    <collision>
      <geometry>
        <cylinder length="0.030" radius="0.070"/>
      </geometry>
      <origin rpy="1.570796 0 0" xyz="0 0 0"/>
    </collision>
    <inertial>
      <origin rpy="0 0 0" xyz="0.0 0.0 0.0"/>
      <mass value="1.5"/>
      <inertia ixx="1.0" ixy="0.0" ixz="0.0" iyy="1.0" iyz="0.0" izz="1.0"/>
    </inertial>
  </link>
  <joint name="wheel_small_right_joint" type="fixed">
    <parent link="caster_small_right_link"/>
    <child link="wheel_small_right_link"/>
    <origin rpy="0 0 0" xyz="0 0 -0.145"/>
    <axis xyz="0 1 0"/>
  </joint>
  <link name="wheel_small_right_link">
    <visual>
      <geometry>
        <cylinder length="0.030" radius="0.070"/>
      </geometry>
      <origin rpy="1.570796 0 0" xyz="0 0 0"/>
      <material name="black"/>
    </visual>
    <collision>
      <geometry>
        <cylinder length="0.030" radius="0.070"/>
      </geometry>
      <origin rpy="1.570796 0 0" xyz="0 0 0"/>
    </collision>
    <inertial>
      <origin rpy="0 0 0" xyz="0.0 0.0 0.0"/>
      <mass value="1.5"/>
      <inertia ixx="1.0" ixy="0.0" ixz="0.0" iyy="1.0" iyz="0.0" izz="1.0"/>
    </inertial>
  </link>
  <joint name="wheel_large_left_joint" type="fixed">
    <parent link="caster_large_left_link"/>
    <child link="wheel_large_left_link"/>
    <origin pry="0 0 0" xyz="0 0 -0.130"/>
    <axis xyz="0 1 0"/>
  </joint>
  <link name="wheel_large_left_link">
    <visual>
      <geometry>
        <cylinder length="0.040" radius="0.080"/>
      </geometry>
      <origin rpy="1.570796 0 0" xyz="0 0 0"/>
      <material name="black"/>
    </visual>
    <collision>
      <geometry>
        <cylinder length="0.040" radius="0.080"/>
      </geometry>
      <origin rpy="1.570796 0 0" xyz="0 0 0"/>
    </collision>
    <inertial>
      <origin rpy="0 0 0" xyz="0.0 0.0 0.0"/>
      <mass value="1.5"/>
      <inertia ixx="1.0" ixy="0.0" ixz="0.0" iyy="1.0" iyz="0.0" izz="1.0"/>
    </inertial>
  </link>
  <joint name="wheel_large_right_joint" type="fixed">
    <parent link="caster_large_right_link"/>
    <child link="wheel_large_right_link"/>
    <origin pry="0 0 0" xyz="0 0 -0.130"/>
    <axis xyz="0 1 0"/>
  </joint>
  <link name="wheel_large_right_link">
    <visual>
      <geometry>
        <cylinder length="0.040" radius="0.080"/>
      </geometry>
      <origin rpy="1.570796 0 0" xyz="0 0 0"/>
      <material name="black"/>
    </visual>
    <collision>
      <geometry>
        <cylinder length="0.040" radius="0.080"/>
      </geometry>
      <origin rpy="1.570796 0 0" xyz="0 0 0"/>
    </collision>
    <inertial>
      <origin rpy="0 0 0" xyz="0.0 0.0 0.0"/>
      <mass value="1.5"/>
      <inertia ixx="1.0" ixy="0.0" ixz="0.0" iyy="1.0" iyz="0.0" izz="1.0"/>
    </inertial>
  </link>
  <joint name="box_joint" type="fixed">
    <parent link="battery_link"/>
    <child link="box_link"/>
    <origin rpy="0 0 0" xyz="0 0 0.450"/>
  </joint>
  <link name="box_link">
    <visual>
      <geometry>
        <box size="0.720 0.500 0.360"/>
      </geometry>
      <origin rpy="0 0 0" xyz="0 0 0"/>
      <material name="gray"/>
    </visual>
    <collision>
      <geometry>
        <box size="0.720 0.500 0.360"/>
      </geometry>
      <origin rpy="0 0 0" xyz="0 0 0"/>
    </collision>
    <inertial>
      <origin rpy="0 0 0" xyz="0.0 0.0 0.0"/>
      <mass value="30"/>
      <inertia ixx="1.0" ixy="0.0" ixz="0.0" iyy="1.0" iyz="0.0" izz="1.0"/>
    </inertial>
  </link>
  <joint name="mast_joint" type="fixed">
    <parent link="box_link"/>
    <child link="mast_link"/>
    <origin rpy="0 0 0" xyz="0 0 0.420"/>
  </joint>
  <link name="mast_link">
    <visual>
      <geometry>
        <box size="0.100 0.100 0.480"/>
      </geometry>
      <origin rpy="0 0 0" xyz="0 0 0"/>
      <material name="lightgray"/>
    </visual>
    <collision>
      <geometry>
        <box size="0.100 0.100 0.480"/>
      </geometry>
      <origin rpy="0 0 0" xyz="0 0 0"/>
    </collision>
    <inertial>
      <origin rpy="0 0 0" xyz="0.0 0.0 0.0"/>
      <mass value="10"/>
      <inertia ixx="1.0" ixy="0.0" ixz="0.0" iyy="1.0" iyz="0.0" izz="1.0"/>
    </inertial>
  </link>
  <joint name="table_joint" type="fixed">
    <parent link="mast_link"/>
    <child link="table_link"/>
    <origin rpy="0 0 0" xyz="0 0 0.246"/>
  </joint>
  <link name="table_link">
    <visual>
      <geometry>
        <box size="0.200 0.200 0.006"/>
      </geometry>
      <origin rpy="0 0 0" xyz="0 0 0"/>
      <material name="ivory"/>
    </visual>
    <collision>
      <geometry>
        <box size="0.200 0.200 0.006"/>
      </geometry>
      <origin rpy="0 0 0" xyz="0 0 0"/>
    </collision>
    <inertial>
      <origin rpy="0 0 0" xyz="0.0 0.0 0.0"/>
      <mass value="1"/>
      <inertia ixx="1.0" ixy="0.0" ixz="0.0" iyy="1.0" iyz="0.0" izz="1.0"/>
    </inertial>
  </link>
  <!-- velodyne -->
  <joint name="velodyne_base_joint" type="fixed">
    <parent link="table_link"/>
    <child link="velodyne_base_link"/>
    <origin rpy="0 0 0" xyz="0 0 0.003"/>
  </joint>
  <link name="velodyne_base_link">
    <visual>
      <geometry>
        <cylinder length="0.058674" radius="0.042672"/>
      </geometry>
      <origin rpy="0 0 0" xyz="0 0 0.029337"/>
      <material name="darkgray"/>
    </visual>
    <collision>
      <geometry>
        <cylinder length="0.058674" radius="0.042672"/>
      </geometry>
      <origin rpy="0 0 0" xyz="0 0 0.029337"/>
    </collision>
    <inertial>
      <origin rpy="0 0 0" xyz="0.0 0.0 0.029337"/>
      <mass value="1.0"/>
      <inertia ixx="1.0" ixy="0.0" ixz="0.0" iyy="1.0" iyz="0.0" izz="1.0"/>
    </inertial>
  </link>
  <joint name="velodyne_top_joint" type="continuous">
    <parent link="velodyne_base_link"/>
    <child link="velodyne_top_link"/>
    <origin rpy="0 0 0" xyz="0 0 0.058674"/>
    <axis xyz="0 0 1"/>
  </joint>
  <link name="velodyne_top_link">
    <visual>
      <geometry>
        <mesh filename="package://infant_description/meshes/velodyne_top.dae"/>
      </geometry>
      <origin rpy="1.570796 0 0" xyz="0 0 0"/>
    </visual>
    <collision>
      <geometry>
        <cylinder length="0.0835714" radius="0.042672"/>
      </geometry>
      <origin rpy="0 0 0" xyz="0 0 0.0417857"/>
    </collision>
    <inertial>
      <origin rpy="0 0 0" xyz="0.0 0.0 0.0417857"/>
      <mass value="0.0001"/>
      <inertia ixx="1.0" ixy="0.0" ixz="0.0" iyy="1.0" iyz="0.0" izz="1.0"/>
    </inertial>
  </link>
  <joint name="velodyne_laser_joint" type="fixed">
    <parent link="velodyne_top_link"/>
    <child link="velodyne_laser_link"/>
    <origin rpy="0 0 0" xyz="0 0 0.02716935"/>
  </joint>
  <link name="velodyne_laser_link">
    <visual>
      <geometry>
        <box size="0.03475311 0.0468099 0.0404979"/>
      </geometry>
      <origin rpy="0 0 0" xyz="0.017376555 0 0"/>
      <material name="lase_black"/>
    </visual>
    <collision>
      <geometry>
        <box size="0.03475311 0.0468099 0.0404979"/>
      </geometry>
      <origin rpy="0 0 0" xyz="0.017376555 0 0"/>
    </collision>
    <inertial>
      <origin rpy="0 0 0" xyz="0.017376555 0.0 0.0"/>
      <mass value="0.0001"/>
      <inertia ixx="1.0" ixy="0.0" ixz="0.0" iyy="1.0" iyz="0.0" izz="1.0"/>
    </inertial>
  </link>
  <!--joint name="velodyne_laser2_joint" type="fixed">
		<parent link="velodyne_top_link"/>
		<child link="velodyne_laser2_link"/>
		<origin xyz="0 0 ${0.0069204+(velodyne_laser_height/2)}" rpy="-${pi/2} 0 ${pi/2}"/>
	</joint>

	<link name="velodyne_laser2_link"/>

	<joint name="velodyne_laser3_joint" type="fixed">
		<parent link="velodyne_top_link"/>
		<child link="velodyne_laser3_link"/>
		<origin xyz="0 0 ${0.0069204+(velodyne_laser_height/2)}" rpy="-${pi/2} 0 ${pi}"/>
	</joint>

	<link name="velodyne_laser3_link"/>
	
	<joint name="velodyne_laser4_joint" type="fixed">
		<parent link="velodyne_top_link"/>
		<child link="velodyne_laser4_link"/>
		<origin xyz="0 0 ${0.0069204+(velodyne_laser_height/2)}" rpy="-${pi/2} 0 -${pi/2}"/>
	</joint>

	<link name="velodyne_laser4_link"/>

	<joint name="velodyne_laser5_joint" type="fixed">
		<parent link="velodyne_top_link"/>
		<child link="velodyne_laser5_link"/>
		<origin xyz="0 0 ${0.0069204+(velodyne_laser_height/2)}" rpy="-${pi/2} 0 ${pi/4}"/>
	</joint>

	<link name="velodyne_laser5_link"/>

	<joint name="velodyne_laser6_joint" type="fixed">
		<parent link="velodyne_top_link"/>
		<child link="velodyne_laser6_link"/>
		<origin xyz="0 0 ${0.0069204+(velodyne_laser_height/2)}" rpy="-${pi/2} 0 ${3*pi/4}"/>
	</joint>

	<link name="velodyne_laser6_link"/>

	<joint name="velodyne_laser7_joint" type="fixed">
		<parent link="velodyne_top_link"/>
		<child link="velodyne_laser7_link"/>
		<origin xyz="0 0 ${0.0069204+(velodyne_laser_height/2)}" rpy="-${pi/2} 0 -${pi/4}"/>
	</joint>

	<link name="velodyne_laser7_link"/>

	<joint name="velodyne_laser8_joint" type="fixed">
		<parent link="velodyne_top_link"/>
		<child link="velodyne_laser8_link"/>
		<origin xyz="0 0 ${0.0069204+(velodyne_laser_height/2)}" rpy="-${pi/2} 0 -${3*pi/4}"/>
	</joint>

	<link name="velodyne_laser8_link"/-->
  <!-- kinect -->
  <joint name="kinect_base_joint" type="fixed">
    <parent link="mast_link"/>
    <child link="kinect_base_link"/>
    <origin rpy="0 0 0" xyz="0.085 0 0"/>
  </joint>
  <link name="kinect_base_link">
    <visual>
      <geometry>
        <box size="0.070 0.080 0.002"/>
      </geometry>
      <origin rpy="0 0 0" xyz="0 0 0"/>
      <material name="gray"/>
    </visual>
    <collision>
      <geometry>
        <box size="0.070 0.080 0.002"/>
      </geometry>
      <origin rpy="0 0 0" xyz="0 0 0"/>
    </collision>
    <inertial>
      <origin rpy="0 0 0" xyz="0.0 0.0 0.0"/>
      <mass value="0.05"/>
      <inertia ixx="1.0" ixy="0.0" ixz="0.0" iyy="1.0" iyz="0.0" izz="1.0"/>
    </inertial>
  </link>
  <joint name="kinect_link_joint" type="fixed">
    <parent link="kinect_base_link"/>
    <child link="kinect_link"/>
    <origin rpy="0 0 0" xyz="0 0 0.052"/>
  </joint>
  <link name="kinect_link"/>
  <joint name="camera_rgb_joint" type="fixed">
    <parent link="kinect_link"/>
    <child link="camera_rgb_frame"/>
    <origin rpy="0 0 0" xyz="0 -0.0125 0"/>
  </joint>
  <link name="camera_rgb_frame"/>
  <joint name="camera_rgb_optical_joint" type="fixed">
    <parent link="camera_rgb_frame"/>
    <child link="camera_rgb_optical_frame"/>
    <origin rpy="-1.570796 0 -1.570796" xyz="0 0 0"/>
  </joint>
  <link name="camera_rgb_optical_frame"/>
  <joint name="camera_joint" type="fixed">
    <parent link="camera_rgb_frame"/>
    <child link="camera_link"/>
    <origin rpy="0 0 0" xyz="0.0 0.0125 -0.016"/>
  </joint>
  <link name="camera_link">
    <visual>
      <geometry>
        <mesh filename="package://infant_description/meshes/kinect.dae"/>
      </geometry>
      <origin rpy="0 0 1.570796" xyz="0 0 0"/>
    </visual>
    <collision>
      <geometry>
        <box size="0.072 0.277 0.073"/>
      </geometry>
      <origin rpy="0 0 0" xyz="0 0 0"/>
    </collision>
    <xacro:default_inertial depth="0.072" height="0.073" mass="0.564" width="0.277" x_offset="0.0" y_offset="0.0" z_offset="0.0"/>
  </link>
  <joint name="camera_depth_joint" type="fixed">
    <parent link="camera_rgb_frame"/>
    <child link="camera_depth_frame"/>
    <origin rpy="0 0 0" xyz="0 0.025 0"/>
  </joint>
  <link name="camera_depth_frame"/>
  <joint name="camera_depth_optical_joint" type="fixed">
    <parent link="camera_depth_frame"/>
    <child link="camera_depth_optical_frame"/>
    <origin rpy="-1.570796 0 -1.570796" xyz="0 0 0"/>
  </joint>
  <link name="camera_depth_optical_frame"/>
  <!-- Dynamixel Arm -->
  <joint name="arm_base_joint" type="fixed">
    <parent link="box_link"/>
    <child link="arm_base_link"/>
    <origin rpy="3.141592 0 0" xyz="0.42 0 0.18"/>
  </joint>
  <link name="arm_base_link">
    <visual>
      <geometry>
        <mesh filename="package://infant_description/meshes/ARM_BODY.dae"/>
      </geometry>
      <origin rpy="0 0 0" xyz="0 0 0"/>
      <material name="gray"/>
    </visual>
    <collision>
      <geometry>
        <box size="0.100 0.100 0.064"/>
      </geometry>
      <origin rpy="0 0 0" xyz="0 0 0.032"/>
    </collision>
    <inertial>
      <origin rpy="0 0 0" xyz="0.0 0.0 -0.02"/>
      <mass value="0.346"/>
      <inertia ixx="1.0" ixy="0.0" ixz="0.0" iyy="1.0" iyz="0.0" izz="1.0"/>
    </inertial>
    <!--inertial>
			<origin xyz="0.0075 0.0000 0.0327" rpy="0 0 0"/>
			<mass value="0.346"/>
			<inertia 
				ixx="0.000324" ixy="0.0" ixz="0.0" 
				iyy="0.000383" iyz="0.0" 
				izz="0.000381"/>
		</inertial-->
  </link>
  <joint name="joint1" type="revolute">
    <parent link="arm_base_link"/>
    <child link="link1"/>
    <origin rpy="0 0 0" xyz="0 0 0.064"/>
    <axis xyz="0 0 1"/>
    <limit effort="6.0" lower="-3.05432555556" upper="3.05432555556" velocity="5.75958533333"/>
  </joint>
  <link name="link1">
    <visual>
      <geometry>
        <mesh filename="package://infant_description/meshes/ARM_JOINT1.dae"/>
      </geometry>
      <origin rpy="1.570796 0 0" xyz="0 0 0"/>
      <material name="gray"/>
    </visual>
    <collision>
      <geometry>
        <box size="0.035 0.070 0.063"/>
      </geometry>
      <origin rpy="0 0 0" xyz="0 0 0.0315"/>
    </collision>
    <inertial>
      <origin rpy="0 0 0" xyz="0.31 0.0 0.025"/>
      <mass value="0.506"/>
      <inertia ixx="1.0" ixy="0.0" ixz="0.0" iyy="1.0" iyz="0.0" izz="1.0"/>
    </inertial>
    <!--inertial>
			<origin xyz="0.0002 0.0367 0.0000" rpy="${pi/2} 0 0"/>
			<mass value="0.506"/>
			<inertia 
				ixx="0.000733" ixy="0.0" ixz="0.0" 
				iyy="0.000495" iyz="0.0" 
				izz="0.000424"/>
		</inertial-->
  </link>
  <joint name="joint2" type="revolute">
    <parent link="link1"/>
    <child link="link2"/>
    <origin rpy="0 0 0" xyz="0 0 0.063"/>
    <axis xyz="0 -1 0"/>
    <limit effort="12.0" lower="-1.65806244444" upper="1.65806244444" velocity="5.75958533333"/>
  </joint>
  <link name="link2">
    <visual>
      <geometry>
        <mesh filename="package://infant_description/meshes/ARM_JOINT2.dae"/>
      </geometry>
      <origin rpy="0 0 0" xyz="0 0 0"/>
      <material name="gray"/>
    </visual>
    <collision>
      <geometry>
        <box size="0.035 0.035 0.250"/>
      </geometry>
      <origin rpy="0 0 0" xyz="0 0 0.125"/>
    </collision>
    <inertial>
      <origin rpy="0 0 0" xyz="0.0 0.0 0.15"/>
      <mass value="0.452"/>
      <inertia ixx="1.0" ixy="0.0" ixz="0.0" iyy="1.0" iyz="0.0" izz="1.0"/>
    </inertial>
    <!--inertial>
			<origin xyz="-0.0083 0.0001 0.1509" rpy="0 0 0"/>
			<mass value="0.452"/>
			<inertia 
				ixx="0.003839" ixy="0.0" ixz="0.000159" 
				iyy="0.000378" iyz="0.0" 
				izz="0.000282"/>
		</inertial-->
  </link>
  <joint name="joint3" type="revolute">
    <parent link="link2"/>
    <child link="link3"/>
    <origin rpy="0 0 0" xyz="0 0 0.250"/>
    <axis xyz="0 -1 0"/>
    <limit effort="6.0" lower="-2.61799333333" upper="0.174532888889" velocity="5.75958533333"/>
  </joint>
  <link name="link3">
    <visual>
      <geometry>
        <mesh filename="package://infant_description/meshes/ARM_JOINT3.dae"/>
      </geometry>
      <origin rpy="0 0 0" xyz="0 0 0"/>
      <material name="gray"/>
    </visual>
    <collision>
      <geometry>
        <box size="0.035 0.035 0.100"/>
      </geometry>
      <origin rpy="0 0 0" xyz="0 0 0.05"/>
    </collision>
    <inertial>
      <origin rpy="0 0 0" xyz="0.0 0.0 0.06"/>
      <mass value="0.232"/>
      <inertia ixx="1.0" ixy="0.0" ixz="0.0" iyy="1.0" iyz="0.0" izz="1.0"/>
    </inertial>
    <!--inertial>
			<origin xyz="-0.0193 0.0003 0.0574" rpy="0 0 0"/>
			<mass value="0.232"/>
			<inertia 
				ixx="0.000230" ixy="0.0" ixz="-0.000164" 
				iyy="0.000231" iyz="0.0" 
				izz="0.000120"/>
		</inertial-->
  </link>
  <joint name="joint4" type="revolute">
    <parent link="link3"/>
    <child link="link4"/>
    <origin rpy="0 0 0" xyz="0 0 0.100"/>
    <axis xyz="0 0 1"/>
    <limit effort="6.0" lower="-3.05432555556" upper="3.05432555556" velocity="5.75958533333"/>
  </joint>
  <link name="link4">
    <visual>
      <geometry>
        <mesh filename="package://infant_description/meshes/ARM_JOINT4.dae"/>
      </geometry>
      <origin rpy="1.570796 0 0" xyz="0 0 0"/>
      <material name="gray"/>
    </visual>
    <collision>
      <geometry>
        <box size="0.035 0.035 0.100"/>
      </geometry>
      <origin rpy="0 0 0" xyz="0 0 0.05"/>
    </collision>
    <inertial>
      <origin rpy="0 0 0" xyz="0.0 0.0 0.04875"/>
      <mass value="0.211"/>
      <inertia ixx="1.0" ixy="0.0" ixz="0.0" iyy="1.0" iyz="0.0" izz="1.0"/>
    </inertial>
    <!--inertial>
			<origin xyz="0.0000 0.0589 0.0000" rpy="${pi/2} 0 0"/>
			<mass value="0.211"/>
			<inertia 
				ixx="0.000307" ixy="0.0" ixz="-0.000164" 
				iyy="0.000061" iyz="0.0" 
				izz="0.000299"/>
		</inertial-->
  </link>
  <joint name="joint5" type="revolute">
    <parent link="link4"/>
    <child link="link5"/>
    <origin rpy="0 0 0" xyz="0 0 0.100"/>
    <axis xyz="0 -1 0"/>
    <limit effort="6.0" lower="-1.65806244444" upper="1.65806244444" velocity="5.75958533333"/>
  </joint>
  <link name="link5">
    <visual>
      <origin rpy="0 0 0" xyz="0 0 0"/>
      <geometry>
        <mesh filename="package://infant_description/meshes/ARM_JOINT5.dae"/>
      </geometry>
      <material name="gray"/>
    </visual>
    <collision>
      <origin rpy="0 0 0" xyz="0 0 0.023"/>
      <geometry>
        <box size="0.024 0.0475 0.046"/>
      </geometry>
    </collision>
    <inertial>
      <origin rpy="0 0 0" xyz="0.0 0.0 0.0305"/>
      <mass value="0.118"/>
      <inertia ixx="1.0" ixy="0.0" ixz="0.0" iyy="1.0" iyz="0.0" izz="1.0"/>
    </inertial>
    <!--inertial>
			<origin xyz="-0.0013 -0.0012 0.0372" rpy="0 0 0"/>
			<mass value="0.118"/>
			<inertia 
				ixx="0.000063" ixy="0.0" ixz="0.0" 
				iyy="0.000050" iyz="0.0" 
				izz="0.000045"/>
		</inertial-->
  </link>
  <joint name="joint6" type="revolute">
    <parent link="link5"/>
    <child link="link6"/>
    <origin rpy="0 0 0" xyz="0 -0.0133 0.046"/>
    <axis xyz="-1 0 0"/>
    <limit effort="6.0" lower="-0.698131555556" upper="0.349065777778" velocity="5.75958533333"/>
  </joint>
  <link name="link6">
    <visual>
      <origin rpy="0 0 -1.570796" xyz="0 0 0"/>
      <geometry>
        <mesh filename="package://infant_description/meshes/ARM_HAND_A.dae"/>
      </geometry>
      <material name="gray"/>
    </visual>
    <collision>
      <origin rpy="0 0 1.570796" xyz="0 0 0"/>
      <geometry>
        <cylinder length="0.0475" radius="0.012"/>
      </geometry>
    </collision>
    <inertial>
      <origin rpy="0 0 0" xyz="0.0 0.0 0.0"/>
      <mass value="0.031"/>
      <inertia ixx="1.0" ixy="0.0" ixz="0.0" iyy="1.0" iyz="0.0" izz="1.0"/>
    </inertial>
    <!--inertial>
			<origin xyz="0.0106 -0.0020 0.0249" rpy="0 0 0"/>
			<mass value="0.031"/>
			<inertia 
				ixx="0.000033" ixy="0.0" ixz="0.0" 
				iyy="0.000027" iyz="0.0" 
				izz="0.000012"/>
		</inertial-->
  </link>
  <joint name="joint7" type="revolute">
    <parent link="link5"/>
    <child link="link7"/>
    <origin rpy="0 0 0" xyz="0 0.0133 0.046"/>
    <axis xyz="-1 0 0"/>
    <limit effort="6.0" lower="-0.698131555556" upper="0.349065777778" velocity="5.75958533333"/>
  </joint>
  <link name="link7">
    <visual>
      <origin rpy="0 0 -1.570796" xyz="0 0 0"/>
      <geometry>
        <mesh filename="package://infant_description/meshes/ARM_HAND_B.dae"/>
      </geometry>
      <material name="gray"/>
    </visual>
    <collision>
      <origin rpy="0 0 -1.570796" xyz="0 0 0"/>
      <geometry>
        <cylinder length="0.0475" radius="0.012"/>
      </geometry>
    </collision>
    <inertial>
      <origin rpy="0 0 0" xyz="0.0 0.0 0.0"/>
      <mass value="0.027"/>
      <inertia ixx="1.0" ixy="0.0" ixz="0.0" iyy="1.0" iyz="0.0" izz="1.0"/>
    </inertial>
    <!--inertial>
			<origin xyz="-0.0119 -0.0036 0.0283" rpy="0 0 0"/>
			<mass value="0.027"/>
			<inertia 
				ixx="0.000029" ixy="0.0" ixz="0.0" 
				iyy="0.000024" iyz="0.0" 
				izz="0.000010"/>
		</inertial-->
  </link>
  <joint name="joint8" type="revolute">
    <parent link="link5"/>
    <child link="link8"/>
    <origin xyz="0 0 0.130"/>
    <axis xyz="0 1 0"/>
    <limit effort="6.0" lower="-0.698131555556" upper="0.610865111111" velocity="5.75958533333"/>
  </joint>
  <link name="link8">
    <visual>
      <origin rpy="0 0 0" xyz="0 0 -0.025"/>
      <geometry>
        <box size="0.06 0.06 0.06"/>
      </geometry>
      <material name="gray"/>
    </visual>
    <collision>
      <origin rpy="0 0 0" xyz="0 0 0"/>
      <geometry>
        <box size="0.06 0.06 0.06"/>
      </geometry>
    </collision>
    <inertial>
      <origin rpy="0 0 0" xyz="0.0 0.0 0.0"/>
      <mass value="0.01"/>
      <inertia ixx="1.0" ixy="0.0" ixz="0.0" iyy="1.0" iyz="0.0" izz="1.0"/>
    </inertial>
  </link>
  <!-- transmission for Dynamixel Arm-->
  <transmission name="tran1">
    <type>transmission_interface/SimpleTransmission</type>
    <joint name="joint1">
      <hardwareInterface>PositionJointInterface</hardwareInterface>
    </joint>
    <actuator name="motor1">
      <hardwareInterface>PositionJointInterface</hardwareInterface>
      <mechanicalReduction>1</mechanicalReduction>
    </actuator>
  </transmission>
  <transmission name="tran2">
    <type>transmission_interface/SimpleTransmission</type>
    <joint name="joint2">
      <hardwareInterface>PositionJointInterface</hardwareInterface>
    </joint>
    <actuator name="motor2">
      <hardwareInterface>PositionJointInterface</hardwareInterface>
      <mechanicalReduction>1</mechanicalReduction>
    </actuator>
  </transmission>
  <transmission name="tran3">
    <type>transmission_interface/SimpleTransmission</type>
    <joint name="joint3">
      <hardwareInterface>PositionJointInterface</hardwareInterface>
    </joint>
    <actuator name="motor3">
      <hardwareInterface>PositionJointInterface</hardwareInterface>
      <mechanicalReduction>1</mechanicalReduction>
    </actuator>
  </transmission>
  <transmission name="tran4">
    <type>transmission_interface/SimpleTransmission</type>
    <joint name="joint4">
      <hardwareInterface>PositionJointInterface</hardwareInterface>
    </joint>
    <actuator name="motor4">
      <hardwareInterface>PositionJointInterface</hardwareInterface>
      <mechanicalReduction>1</mechanicalReduction>
    </actuator>
  </transmission>
  <transmission name="tran5">
    <type>transmission_interface/SimpleTransmission</type>
    <joint name="joint5">
      <hardwareInterface>PositionJointInterface</hardwareInterface>
    </joint>
    <actuator name="motor5">
      <hardwareInterface>PositionJointInterface</hardwareInterface>
      <mechanicalReduction>1</mechanicalReduction>
    </actuator>
  </transmission>
  <transmission name="tran6">
    <type>transmission_interface/SimpleTransmission</type>
    <joint name="joint6">
      <hardwareInterface>PositionJointInterface</hardwareInterface>
    </joint>
    <actuator name="motor6">
      <hardwareInterface>PositionJointInterface</hardwareInterface>
      <mechanicalReduction>1</mechanicalReduction>
    </actuator>
  </transmission>
  <transmission name="tran7">
    <type>transmission_interface/SimpleTransmission</type>
    <joint name="joint7">
      <hardwareInterface>PositionJointInterface</hardwareInterface>
    </joint>
    <actuator name="motor7">
      <hardwareInterface>PositionJointInterface</hardwareInterface>
      <mechanicalReduction>1</mechanicalReduction>
    </actuator>
  </transmission>
  <transmission name="tran8">
    <type>transmission_interface/SimpleTransmission</type>
    <joint name="joint8">
      <hardwareInterface>PositionJointInterface</hardwareInterface>
    </joint>
    <actuator name="motor8">
      <hardwareInterface>PositionJointInterface</hardwareInterface>
      <mechanicalReduction>1</mechanicalReduction>
    </actuator>
  </transmission>
  <!-- transmission -->
  <transmission name="wheel_left_trans">
    <type>transmission_interface/SimpleTransmission</type>
    <joint name="wheel_left_joint">
      <hardwareInterface>VelocityJointInterface</hardwareInterface>
    </joint>
    <actuator name="wheel_left_motor">
      <hardwareInterface>VelocityJointInterface</hardwareInterface>
      <mechanicalReduction>1</mechanicalReduction>
    </actuator>
  </transmission>
  <transmission name="wheel_right_trans">
    <type>transmission_interface/SimpleTransmission</type>
    <joint name="wheel_right_joint">
      <hardwareInterface>VelocityJointInterface</hardwareInterface>
    </joint>
    <actuator name="wheel_right_motor">
      <hardwareInterface>VelocityJointInterface</hardwareInterface>
      <mechanicalReduction>1</mechanicalReduction>
    </actuator>
  </transmission>
  <transmission name="velodyne_top_trans">
    <type>transmission_interface/SimpleTransmission</type>
    <joint name="velodyne_top_joint">
      <hardwareInterface>VelocityJointInterface</hardwareInterface>
    </joint>
    <actuator name="velodyne_top_motor">
      <hardwareInterface>VelocityJointInterface</hardwareInterface>
      <mechanicalReduction>1</mechanicalReduction>
    </actuator>
  </transmission>
</robot>

